<?xml version="1.0" ?>
<!-- =================================================================================== -->
<!-- |    This document was autogenerated by xacro from mydogrobot.urdf.xacro          | -->
<!-- |    EDITING THIS FILE BY HAND IS NOT RECOMMENDED                                 | -->
<!-- =================================================================================== -->
<robot name="mydogrobot">
  <material name="red">
    <color rgba="1.0 0.0 0.0 1.0"/>
  </material>
  <material name="blue">
    <color rgba="0.0 0.0 1.0 1.0"/>
  </material>
  <material name="yellow">
    <color rgba="0.0 1.0 0.0 1.0"/>
  </material>
  <!--BODY部分-->
  <link name="base_link">
    <visual>
      <geometry>
        <mesh filename="package://mydogrobot_description/stl/body.stl"/>
      </geometry>
      <origin rpy="0 0 0" xyz="0 0 0"/>
      <material name="blue"/>
    </visual>
  </link>
  <!--BODY_frontleg_r間のジョイント-->
  <joint name="backleg_r_joint" type="revolute">
    <parent link="base_link"/>
    <child link="backleg_r_link"/>
    <axis xyz="1 0 0"/>
    <origin xyz="0.007 -0.0385 0"/>
    <limit effort="0" lower="-1.5" upper="1.5" velocity="0"/>
  </joint>
  <joint name="backleg_l_joint" type="revolute">
    <parent link="base_link"/>
    <child link="backleg_l_link"/>
    <axis xyz="1 0 0"/>
    <origin xyz="0.007 0.0385 0"/>
    <limit effort="0" lower="-1.5" upper="1.5" velocity="0"/>
  </joint>
  <joint name="frontleg_r_joint" type="revolute">
    <parent link="base_link"/>
    <child link="frontleg_r_link"/>
    <axis xyz="1 0 0"/>
    <origin xyz="0.143 -0.0385 0"/>
    <limit effort="0" lower="-1.5" upper="1.5" velocity="0"/>
  </joint>
  <joint name="frontleg_l_joint" type="revolute">
    <parent link="base_link"/>
    <child link="frontleg_l_link"/>
    <axis xyz="1 0 0"/>
    <origin xyz="0.143 0.0385 0"/>
    <limit effort="0" lower="-1.5" upper="1.5" velocity="0"/>
  </joint>
  <joint name="frontfoot_r_joint" type="revolute">
    <parent link="frontleg_r_link"/>
    <child link="frontfoot_r_link"/>
    <axis xyz="0 1 0"/>
    <origin xyz="0.153 -0.05 -0.025"/>
    <limit effort="0" lower="-1.5" upper="1.5" velocity="0"/>
  </joint>
  <joint name="frontfoot_l_joint" type="revolute">
    <parent link="frontleg_l_link"/>
    <child link="frontfoot_l_link"/>
    <axis xyz="0 1 0"/>
    <origin xyz="0.153 0.05 -0.025"/>
    <limit effort="0" lower="-1.5" upper="1.5" velocity="0"/>
  </joint>
  <joint name="backfoot_r_joint" type="revolute">
    <parent link="backleg_r_link"/>
    <child link="backfoot_r_link"/>
    <axis xyz="0 1 0"/>
    <origin xyz="0.017 -0.05 -0.025"/>
    <limit effort="0" lower="-1.5" upper="1.5" velocity="0"/>
  </joint>
  <joint name="backfoot_l_joint" type="revolute">
    <parent link="backleg_l_link"/>
    <child link="backfoot_l_link"/>
    <axis xyz="0 1 0"/>
    <origin xyz="0.017 0.05 -0.025"/>
    <limit effort="0" lower="-1.5" upper="1.5" velocity="0"/>
  </joint>
  <joint name="head_joint" type="revolute">
    <parent link="base_link"/>
    <child link="head_link"/>
    <axis xyz="0 1 0"/>
    <origin xyz="0.205 0 0.0"/>
    <limit effort="0" lower="-1.5" upper="1.5" velocity="0"/>
  </joint>
  <!--backleg_r部分-->
  <link name="backleg_r_link">
    <visual>
      <geometry>
        <mesh filename="package://mydogrobot_description/stl/leg_r.stl"/>
      </geometry>
      <origin rpy="0 0 0" xyz="0 0 0"/>
      <material name="red"/>
    </visual>
  </link>
  <!--backleg_l部分-->
  <link name="backleg_l_link">
    <visual>
      <geometry>
        <mesh filename="package://mydogrobot_description/stl/leg_l.stl"/>
      </geometry>
      <origin rpy="0 0 0" xyz="0 0 0"/>
      <material name="red"/>
    </visual>
  </link>
  <!--frontleg_r部分-->
  <link name="frontleg_r_link">
    <visual>
      <geometry>
        <mesh filename="package://mydogrobot_description/stl/leg_r.stl"/>
      </geometry>
      <origin rpy="0 0 0" xyz="0 0 0"/>
      <material name="red"/>
    </visual>
  </link>
  <!--frontleg_l部分-->
  <link name="frontleg_l_link">
    <visual>
      <geometry>
        <mesh filename="package://mydogrobot_description/stl/leg_l.stl"/>
      </geometry>
      <origin rpy="0 0 0" xyz="0 0 0"/>
      <material name="red"/>
    </visual>
  </link>
  <link name="frontfoot_l_link">
    <visual>
      <geometry>
        <mesh filename="package://mydogrobot_description/stl/foot_l.stl"/>
      </geometry>
      <origin rpy="0 0 0" xyz="0 0 0 "/>
      <material name="yellow"/>
    </visual>
  </link>
  <link name="frontfoot_r_link">
    <visual>
      <geometry>
        <mesh filename="package://mydogrobot_description/stl/foot_r.stl"/>
      </geometry>
      <origin rpy="0 0 0" xyz="0 0 0"/>
      <material name="yellow"/>
    </visual>
  </link>
  <link name="backfoot_l_link">
    <visual>
      <geometry>
        <mesh filename="package://mydogrobot_description/stl/foot_l.stl"/>
      </geometry>
      <origin rpy="0 0 0" xyz="0 0 0"/>
      <material name="yellow"/>
    </visual>
  </link>
  <link name="backfoot_r_link">
    <visual>
      <geometry>
        <mesh filename="package://mydogrobot_description/stl/foot_r.stl"/>
      </geometry>
      <origin rpy="0 0 0" xyz="0 0 0"/>
      <material name="yellow"/>
    </visual>
  </link>
  <link name="head_link">
    <visual>
      <geometry>
        <mesh filename="package://mydogrobot_description/stl/head.stl"/>
      </geometry>
      <origin rpy="0 0 0" xyz="0.02 0 0"/>
      <material name="read"/>
    </visual>
  </link>
</robot>
